<?xml version="1.0"?>
<robot name="gopigo3">
  <ros2_control name="gpg_remote" type="system">
    <hardware>
      <plugin>gpg_remote/GPGRemoteHardware</plugin>
      <param name="host">192.168.0.204</param>
      <param name="port">8002</param>
    </hardware>
    
    <joint name="left_wheel">
      <command_interface name="velocity"/>
      <state_interface name="position"/>
      <state_interface name="velocity"/>  
    </joint>
    <joint name="right_wheel">
      <command_interface name="velocity"/>
      <state_interface name="position"/>
      <state_interface name="velocity"/>  
    </joint>
    <joint name="servo">
      <command_interface name="position"/>
      <state_interface name="position"/>
    </joint>
    <sensor name="line">
       <state_interface name="level0"/>
       <state_interface name="level1"/>
       <state_interface name="level2"/>
       <state_interface name="level3"/>
       <state_interface name="level4"/>
    </sensor>
    <sensor name="battery">
       <state_interface name="voltage"/>
    </sensor>
  </ros2_control>
  
  <material name="blue">
        <color rgba="0 0 0.8 1"/>
    </material>
    <material name="white">
        <color rgba="1 1 1 1"/>
  </material>
  
  <link name="base_link">
        <visual>
            <geometry>
                <cylinder length="0.005" radius="0.075"/><!--<cylinder length="0.08" radius="0.075"/>-->
            </geometry>
            <origin xyz="0 0 0.0375" rpy="0 0 0"/><!--<origin xyz="0 0 0.0575" rpy="0 0 0"/>-->
            <material name="white"/>
        </visual>
  </link>
  
  <link name="right_wheel_link">
        <visual>
            <geometry>
                <cylinder length="0.04" radius="0.0375"/>
            </geometry>
            <origin xyz="0 0 0" rpy = "1.57 0 0"/>
            <material name="blue"/>
        </visual>
  </link>

  <joint name="right_wheel" type="continuous">
        <axis xyz="0 1 0"/>
        <origin xyz="0 -0.062 0.0375" rpy="0 0 0"/> 
        <parent link="base_link"/>
        <child link="right_wheel_link"/>
  </joint>
  
  <link name="left_wheel_link">
        <visual>
            <geometry>
                <cylinder length="0.04" radius="0.0375"/>
            </geometry>
            <origin xyz="0 0 0" rpy="1.57 0 0"/>
            <material name="blue"/>
        </visual>
  </link>

  <joint name="left_wheel" type="continuous">
        <axis xyz="0 1 0"/>
        <origin xyz="0 0.062 0.0375" rpy="0 0 0"/> 
        <parent link="base_link"/>
        <child link="left_wheel_link"/>
  </joint>
  
  <link name="servo_link">
        <visual>
            <geometry>
                <box size="0.03 0.03 0.03"/> 
            </geometry>
            <material name="blue"/>
            <origin xyz="0 0 0" rpy="0 0 0"/>
        </visual>
  </link>
  
  <joint name="servo" type="revolute">
        <axis xyz="0 0 1"/> 
        <limit lower="-1.57" upper="1.57" effort="1" velocity="1"/>
        <origin xyz="0.075 0 0.065" rpy="0 0 0"/>
        <parent link="base_link"/>
        <child link="servo_link"/>
  </joint>
  
  <link name="camera_link">
      <visual>
          <geometry>
              <box size="0.01 0.01 0.01"/>
          </geometry>
          <origin xyz="0 0 0" rpy="0 0 0"/>
          <material name="white"/>
      </visual>
  </link>
  
  <joint name="camera_to_servo_link" type="fixed">
        <origin xyz="0.015 0 0" rpy="-1.57 0 0"/>
        <parent link="servo_link"/>
        <child link="camera_link"/>
  </joint>
  
</robot>
