<?xml version="1.0"?>
<robot name="simplified_gopigo3_model">
    <material name="blue">
        <color rgba="0 0 0.8 1"/>
    </material>
    <material name="white">
        <color rgba="1 1 1 1"/>
    </material>
  
    <link name="base_link">
        <visual>
            <geometry>
                <cylinder length="0.005" radius="0.075"/><!--<cylinder length="0.08" radius="0.075"/>-->
            </geometry>
            <origin xyz="0 0 0.0375" rpy="0 0 0"/><!--<origin xyz="0 0 0.0575" rpy="0 0 0"/>-->
            <material name="white"/>
        </visual>
    </link>

    <link name="servo_link">
        <visual>
            <geometry>
                <box size="0.03 0.03 0.03"/> 
            </geometry>
            <material name="blue"/>
            <origin xyz="0 0 0" rpy="0 0 0"/>
        </visual>
    </link>

    <link name="left_wheel_link">
        <visual>
            <geometry>
                <cylinder length="0.04" radius="0.0375"/>
            </geometry>
            <origin xyz="0 0 0" rpy="1.57 0 0"/>
            <material name="blue"/>
        </visual>
    </link>
    
    <link name="right_wheel_link">
        <visual>
            <geometry>
                <cylinder length="0.04" radius="0.0375"/>
            </geometry>
            <origin xyz="0 0 0" rpy = "1.57 0 0"/>
            <material name="blue"/>
        </visual>
    </link>
    
    <link name="camera_link">
      <visual>
          <geometry>
              <box size="0.01 0.01 0.01"/>
          </geometry>
          <origin xyz="0 0 0" rpy="0 0 0"/>
          <material name="white"/>
      </visual>
    </link>

    <joint name="servo" type="revolute">
        <axis xyz="0 0 1"/> 
        <limit lower="-1.57" upper="1.57" effort="1" velocity="1"/>
        <origin xyz="0.075 0 0.065" rpy="0 0 0"/>
        <parent link="base_link"/>
        <child link="servo_link"/>
    </joint>
    
    <joint name="left_wheel" type="continuous">
        <axis xyz="0 1 0"/>
        <origin xyz="0 0.062 0.0375" rpy="0 0 0"/> 
        <parent link="base_link"/>
        <child link="left_wheel_link"/>
    </joint>
    
    <joint name="right_wheel" type="continuous">
        <axis xyz="0 1 0"/>
        <origin xyz="0 -0.062 0.0375" rpy="0 0 0"/> 
        <parent link="base_link"/>
        <child link="right_wheel_link"/>
    </joint>
    
    <joint name="camera_to_servo_link" type="fixed">
        <origin xyz="0.015 0 0" rpy="-1.57 0 0"/>
        <parent link="servo_link"/>
        <child link="camera_link"/>
    </joint>

</robot>
